<robot name="raspbot_omniwheel" xmlns:xacro="http://ros.org/wiki/xacro"  >

    <xacro:macro name="raspbot_omniwheel">

        <!-- omniwheel part-->
        <link name="omniwheel_part1_link">
            <inertial>
                <mass value="0.016" />
                <origin xyz="0 0 0" />
                <inertia ixx="2.23E-06" ixy="0" ixz="0" 
                    iyy="3.77E-06" iyz="0" 
                    izz="1.568E-06" />
            </inertial>
            <visual>
                <origin xyz="0 0 0" rpy="0 0 0" />
                <geometry>
                    <mesh filename="package://raspbot_description/meshes/omniwheel_part1.dae" />
                </geometry>
            </visual>
            <collision>
                <origin xyz="0 0 0" rpy="0 0 0" />
                <geometry>
                    <box size="0.039 0.033 0.002"/>
                </geometry>
            </collision>
        </link>
        <joint name="base_omniwheel_part1_joint" type="fixed">
            <origin xyz="${omniwheel_x_offset} 0 ${omniwheel_vertical_offset}" rpy="0 0 0" />
            <parent link="base_link" />
            <child link="omniwheel_part1_link" />
        </joint>

        <link name="omniwheel_part2_link">
            <inertial>
                <mass value="0.031" />
                <origin xyz="-0.0035 0 0.007" />
                <!-- <inertia ixx="3.91E-07" ixy="0" ixz="0" 
                    iyy="4.709E-07" iyz="0" 
                    izz="3.97E-07" /> -->
                <inertia ixx="0.031" ixy="0" ixz="0" 
                    iyy="0.031" iyz="0" 
                    izz="0.031" />    
            </inertial>
            <visual>
                <origin xyz="0 0 0" rpy="0 0 0" />
                <geometry>
                    <mesh filename="package://raspbot_description/meshes/omniwheel_part2.dae" />
                </geometry>
            </visual>
            <collision>
                <origin xyz="0 0 0" rpy="0 0 0" />
                <geometry>
                    <cylinder length="0.01" radius="0.02" />
                </geometry>
            </collision>
        </link>
        <joint name="omniwheel_part1_2_joint" type="continuous">
            <origin xyz="0 0 -0.01638" rpy="0 0 0" />
            <parent link="omniwheel_part1_link" />
            <child link="omniwheel_part2_link" />
            <axis xyz="0 0 1" rpy="0 0 0" />
        </joint>

        <link name="omniwheel_part3_link">
            <inertial>
                <mass value="0.02" />
                <origin xyz="0 0 0" />
                <inertia ixx="1.504E-06" ixy="0" ixz="0" 
                iyy="1.07E-06" iyz="0" 
                izz="1.07E-06" />
            </inertial>
            <visual>
                <origin xyz="0 0 0" rpy="0 0 0" />
                <geometry>
                    <mesh filename="package://raspbot_description/meshes/omniwheel_part3.dae" />
                </geometry>
            </visual>
            <collision>
                <origin xyz="-0.015 0 0" rpy="0 0 0" />
                <geometry>
                    <cylinder length="0.025" radius="0.028" />
                </geometry>
            </collision>
        </link>
        <joint name="omniwheel_part2_3_joint" type="continuous">
            <origin xyz="-0.015 0 -0.00718" rpy="0 0 0" />
            <parent link="omniwheel_part2_link" />
            <child link="omniwheel_part3_link" />
            <axis xyz="0 1 0" rpy="0 0 0" />
        </joint>

        <gazebo reference="omniwheel_part2_link">
			<mu1 value="0.5"/>
			<mu2 value="0.5"/>
			<kp value="10000000.0" />
			<kd value="1.0" />
			<fdir1 value="1 0 0"/>
            
		</gazebo>     

        <gazebo reference="omniwheel_part3_link">
			<mu1 value="1"/>
			<mu2 value="1"/>
			<kp value="10000000.0" />
			<kd value="1.0" />
			<fdir1 value="1 0 0"/>
		</gazebo>

    </xacro:macro>

</robot>
