<robot name="raspbot_omniwheel" xmlns:xacro="http://ros.org/wiki/xacro"  >

    <xacro:macro name="raspbot_omniwheel">

        <!-- omniwheel part-->
        <link name="omniwheel_part1_link">
            <inertial>
                <mass value="0.01" />
                <origin xyz="0 0 0" />
                <inertia ixx="0.01" ixy="0" ixz="0" iyy="0.01" iyz="0" izz="0.01" />
            </inertial>
            <visual>
                <origin xyz="0 0 0" rpy="0 0 0" />
                <geometry>
                    <mesh filename="package://raspbot_description/meshes/omniwheel_part1.dae" />
                </geometry>
            </visual>
            <collision>
                <origin xyz="0 0 0" rpy="0 0 0" />
                <geometry>
                    <box size="0.039 0.033 0.002"/>
                </geometry>
            </collision>
        </link>
        <joint name="base_omniwheel_part1_joint" type="fixed">
            <origin xyz="${omniwheel_x_offset} 0 ${omniwheel_vertical_offset}" rpy="0 0 0" />
            <parent link="base_link" />
            <child link="omniwheel_part1_link" />
        </joint>

        <link name="omniwheel_part2_link">
            <inertial>
                <mass value="1" />
                <origin xyz="0 0 0" />
                <inertia ixx="1" ixy="0" ixz="0" 
                    iyy="1" iyz="0" 
                    izz="1" />
            </inertial>
            <visual>
                <origin xyz="0 0 0" rpy="0 0 0" />
                <geometry>
                    <mesh filename="package://raspbot_description/meshes/omniwheel_part2.dae" />
                </geometry>
            </visual>
            <collision>
                <origin xyz="0 0 0" rpy="0 0 0" />
                <geometry>
                    <cylinder length="0.01" radius="0.02" />
                </geometry>
            </collision>
        </link>
        <joint name="omniwheel_part1_2_joint" type="continuous">
            <origin xyz="0 0 -0.01638" rpy="0 0 0" />
            <parent link="omniwheel_part1_link" />
            <child link="omniwheel_part2_link" />
            <axis xyz="0 0 1" rpy="0 0 0" />
        </joint>

        <link name="omniwheel_part3_link">
            <inertial>
                <mass value="0.01" />
                <origin xyz="0 0 0" />
                <inertia ixx="0.001" ixy="0" ixz="0" 
                iyy="0.001" iyz="0" 
                izz="0.001" />
            </inertial>
            <visual>
                <origin xyz="0 0 0" rpy="0 0 0" />
                <geometry>
                    <mesh filename="package://raspbot_description/meshes/omniwheel_part3.dae" />
                </geometry>
            </visual>
            <collision>
                <origin xyz="-0.015 0 0" rpy="0 0 0" />
                <geometry>
                    <cylinder length="0.025" radius="0.028" />
                </geometry>
            </collision>
        </link>
        <joint name="omniwheel_part2_3_joint" type="continuous">
            <origin xyz="-0.015 0 -0.00718" rpy="0 0 0" />
            <parent link="omniwheel_part2_link" />
            <child link="omniwheel_part3_link" />
            <axis xyz="0 1 0" rpy="0 0 0" />
        </joint>

        <gazebo reference="omniwheel_part2_link">
			<mu1 value="0.01"/>
			<mu2 value="0.01"/>
			<kp value="10000000.0" />
			<kd value="1.0" />
			<fdir1 value="1 0 0"/>
		</gazebo>     

        <gazebo reference="omniwheel_part3_link">
			<mu1 value="0.1"/>
			<mu2 value="0.1"/>
			<kp value="10000000.0" />
			<kd value="1.0" />
			<fdir1 value="1 0 0"/>
		</gazebo>

    </xacro:macro>

</robot>

