<?xml version="1.0"?>

<robot xmlns:xacro="http://ros.org/wiki/xacro" name="raspbot_wheel" >

    <xacro:macro name="raspbot_wheel" params="wheel_prefix *joint_pose  *axis">
        <link name="${wheel_prefix}_wheel_link">
        	<inertial>
				<mass value="0.034" />
				<origin xyz="0 0 0" />
				<inertia  ixx="0.034" ixy="0" ixz="0" 
					iyy="0.034" iyz="0" 
					izz="0.034" />
			</inertial>
            <visual>
                <origin xyz="0 0 0" rpy="0 0 0" />
                <geometry>
                    <mesh filename="package://raspbot_description/meshes/wheel.dae" />
                </geometry>
            </visual>
			<collision>
				<origin xyz="0 0 0" rpy="${M_PI/2} 0 0" />
				<geometry>
					<cylinder length="${wheel_length}" radius="${wheel_radius}" />
				</geometry>
			</collision>
        </link>

        <joint name="${wheel_prefix}_wheel" type="continuous">
            <parent link="base_link"/>
            <child link="${wheel_prefix}_wheel_link"/>
            <xacro:insert_block name="joint_pose"/>
            <xacro:insert_block name="axis"/>
        </joint>

		<gazebo reference="${wheel_prefix}_wheel_link">
			<mu1 value="1.0"/>
			<mu2 value="1.0"/>
			<kp value="10000000.0" />
			<kd value="1.0" />
			<fdir1 value="1 0 0"/>
		</gazebo>

		<transmission name="${wheel_prefix}_wheel_trans" type="SimpleTransmission">
			<type>transmission_interface/SimpleTransmission</type>
			<joint name="${wheel_prefix}_wheel">
				<hardwareInterface>hardware_interface/VelocityJointInterface</hardwareInterface>
			</joint>
			<actuator name="${wheel_prefix}_wheel_motor">
				<hardwareInterface>hardware_interface/VelocityJointInterface</hardwareInterface>
				<mechanicalReduction>1</mechanicalReduction>
			</actuator>

		</transmission>

    </xacro:macro>
</robot>
